Workbook

Sheet Sheet1
A1: Item Number | B1: Item Description | C1: Item Segment | D1: HS-Code
A2: 1109656820 | B2: CHEESEMATE 3036 | C2: Savory | D2: A210600
A3: OVP-L | B3: OVP-L - 25KG | C3: Savory | D3: A210600
A4: 077001020 | B4: FD&C RED NO.40 POWDER 20KG | C4: Colors | D4: A320400
A5: 1050478800 | B5: PROTEX 2617 - 25KG | C5: Savory | D5: A210600
A6: IDF2005 | B6: DB XF1951 10KG | C6: Sweet | D6: A210600
A7: 2024444 | B7: CINNABON Caramel Topping | C7: Sweet | D7: A210600
A8: 03509A014 | B8: PEACH ORANGE 13.5KG | C8: Colors | D8: A320400
A9: IDF2004 | B9: DB XF1591 10KG | C9: Sweet | D9: A210600
A10: 093101020 | B10: FD&C RED 40 ALLK 35-42% (20KG) | C10: Colors | D10: A320400
A11: M86030020 | B11: EUROCERT TARTRAZINE BG 311050 | C11: Colors | D11: A320400
A12: IDF2017 | B12: DB N2945 (FML10) 10KG | C12: Sweet | D12: A210600
... A182: 096061020 | B182: FD&C YELLOW 6 ALLK 17-19% 20KG | C182: Colors | D182: A320400
A183: 355.005 | B183: #N/A | C183: #N/A
A184: 11100488 | B184: CARMINE LAKE 30% | C184: Colors | D184: A320400
A185: 036431020 | B185: BERRY MICROFINE 20KG | C185: Colors | D185: A320400
A186: 409541-0010 | B186: RUBY RED P-WS | C186: Colors | D186: A320400
A187: 096101020 | B187: FD&C YELLOW 6 ALLK 35-42% 20KG | C187: Colors | D187: A320400
A188: 951090B003 | B188: CINNABON CARAMEL TOPPING @ | C188: Dairy | D188: A210600
A189: 096231020 | B189: FD&C YELLOW 6 AL LK20-24% 20KG | C189: Colors | D189: A320400
A190: 503750.010 | B190: MIDNIGHT BLACK P-WD 10KG | C190: Colors | D190: A320400
A191: C86040O20 | B191: EUROCERT SUNSET YELLOW BG | C191: Colors | D191: A320400
A192: 509231320 | B192: BLACK IRON OXIDE 509231320 | C192: Colors | D192: A320400
A193: 503262.010 | B193: RASPBERRY RED P-WS 10KG | C193: Colors | D193: A320400
A194: M98110C20 | B194: RED NO 5 E 122 EXTRUKLEEN | C194: Colors | D194: A320400
A195: 97CB0781 | B195: NATURAL CAROTENE EMULSION | C195: Colors | D195: A320400
... A260: 9640600020 | B260: VEGAN DB COND MILK FL N14136 | C260: Sweet | D260: A210600

Sheet TDP
A5: PT. Sensient Technologies Indonesia
A6: Date - Period | B6: StatusType | C6: Order Type | D6: Invoice | E6: Customer Order | F6: Order | G6: Ship Date | H6: Customer Group | I6: Item Number | J6: Item Description | K6: Input Quantity | L6: Input UOM | M6: Total KG | N6: Unit Price | O6: Amount | P6: Amount - Sales and orders Only | Q6: Foreign per unit | R6: Foreign Amount | S6: Currency | T6: StandardCost | U6: StandardCost- Sales and orders Only | V6: Gross Margin | W6: Gross Margin % | X6: Margin - Sales and orders Only | Y6: IncoTerms | Z6: IncoTerms Description | AA6: Ship To | AB6: Ship To Name | AC6: Sales Region Desc | AD6: Sales Region | AE6: Delivery Days | AF6: GL Category | AG6: Cat6 | AH6: Cat 6 Desc | AI6: Cat7 | AJ6: Cat 7 Desc | AK6: SaleType | AL6: AffiliateType | AM6: CustomerType | AN6: HS-Code | AP6: Note Finance MB
A7: 45658 | B7: Invoiced | C7: SO | D7: 25707908 | E7: 24106304 | F7: 241200149 | G7: 45659 | H7: PT. TIGAKA DISTRINDO PERKASA JAKARTA | I7: 096091020 | J7: FD&C YELLOW 5 ALLK 35-42% 20KG | K7: 300 | L7: KG | M7: 300 | N7: 386598.59 | O7: 115979577 | P7: 115979577 | Q7: 0 | R7: 0 | S7: IDR | T7: 90253620 | U7: 90253620 | V7: 25725957 | W7: 0.22181454 | X7: 25725957 | Y7: DEL | Z7: Delivered | AA7: 15159 | AB7: PT. TIGAKA DISTRINDO PERKASA CIKARANG | AC7: ELLY HENDRA | AD7: 35 | AE7: 0 | AF7: 963 | AG7: TCSK | AH7: TRA COL SYN LAKE | AJ7: . | AK7: T | AL7: Non-Affiliate | AM7: Distributor | AN7: =VLOOKUP(I7,Sheet1!A:D,4,) -> A320400 | AP7: Invoaice di kasih sore jam pulang kerja jam 17:38.invoaice tanggal 2,10/1/25. MB terima di tanggal 17/1/25. Cortexnya masih belum bisa.
A8: 45658 | B8: Invoiced | C8: SO | D8: 25707908 | E8: 24106304 | F8: 241200149 | G8: 45659 | H8: PT. TIGAKA DISTRINDO PERKASA JAKARTA | I8: 077001020 | J8: FD&C RED NO.40 POWDER 20KG | K8: 220 | L8: KG | M8: 220 | N8: 457480.42 | O8: 1.0064569e+08 | P8: 1.0064569e+08 | Q8: 0 | R8: 0 | S8: IDR | T8: 52666862 | U8: 52666862 | V8: 47978830 | W8: 0.47671022 | X8: 47978830 | Y8: DEL | Z8: Delivered | AA8: 15159 | AB8: PT. TIGAKA DISTRINDO PERKASA CIKARANG | AC8: ELLY HENDRA | AD8: 35 | AE8: 0 | AF8: 961 | AG8: TCSP | AH8: TRA COL SYN DYE POWDER | AJ8: . | AK8: T | AL8: Non-Affiliate | AM8: Distributor | AN8: =VLOOKUP(I8,Sheet1!A:D,4,) -> A320400 | AP8: Invoaice di kasih sore jam pulang kerja jam 17:38.invoaice tanggal 2,10/1/25. MB terima di tanggal 17/1/25. Cortexnya masih belum bisa.
A9: 45658 | B9: Invoiced | C9: SO | D9: 25707909 | E9: 24106305 | F9: 241100199 | G9: 45659 | H9: PT. TIGAKA DISTRINDO PERKASA PHARMA | I9: 056011020 | J9: FD&C BLUE NO 1 POWDER 20KG | K9: 100 | L9: KG | M9: 100 | N9: 715321.2 | O9: 71532120 | P9: 71532120 | Q9: 0 | R9: 0 | S9: IDR | T9: 55963280 | U9: 55963280 | V9: 15568840 | W9: 0.21764824 | X9: 15568840 | Z9: . | AA9: 2306153 | AB9: PT. TIGAKA DISTRINDO PERKASA PHARMA | AC9: ELLY HENDRA | AD9: 35 | AE9: 0 | AF9: 961 | AG9: TCSP | AH9: TRA COL SYN DYE POWDER | AJ9: . | AK9: T | AL9: Non-Affiliate | AM9: Distributor | AN9: =VLOOKUP(I9,Sheet1!A:D,4,) -> A320400 | AP9: Invoaice di kasih sore jam pulang kerja jam 17:38.invoaice tanggal 2,10/1/25. MB terima di tanggal 17/1/25. Cortexnya masih belum bisa.
A10: 45658 | B10: Invoiced | C10: SO | D10: 25707909 | E10: 24106305 | F10: 241100199 | G10: 45659 | H10: PT. TIGAKA DISTRINDO PERKASA PHARMA | I10: K71811020 | J10: D&C YELLW #10 ALLK 14-18% 20KG | K10: 200 | L10: KG | M10: 200 | N10: 906832.19 | O10: 181366438 | P10: 181366438 | Q10: 0 | R10: 0 | S10: IDR | T10: 95025018 | U10: 95025018 | V10: 86341420 | W10: 0.47606063 | X10: 86341420 | Z10: . | AA10: 2306153 | AB10: PT. TIGAKA DISTRINDO PERKASA PHARMA | AC10: ELLY HENDRA | AD10: 35 | AE10: 0 | AF10: 961 | AG10: TMCC | AH10: TRA COS COSMETIC COLOUR | AJ10: . | AK10: T | AL10: Non-Affiliate | AM10: Distributor | AN10: =VLOOKUP(I10,Sheet1!A:D,4,) -> A320400 | AP10: Invoaice di kasih sore jam pulang kerja jam 17:38.invoaice tanggal 2,10/1/25. MB terima di tanggal 17/1/25. Cortexnya masih belum bisa.
A11: 45658 | B11: Invoiced | C11: SO | D11: 25707910 | E11: 24106355 | F11: 241100227 | G11: 45659 | H11: PT. TIGAKA DISTRINDO PERKASA PHARMA | I11: 503262.010 | J11: RASPBERRY RED P-WS 10KG | K11: 1800 | L11: KG | M11: 1800 | N11: 410282.59 | O11: 738508662 | P11: 738508662 | Q11: 0 | R11: 0 | S11: IDR | T11: 3.2545827e+08 | U11: 3.2545827e+08 | V11: 4.1305039e+08 | W11: 0.55930338 | X11: 4.1305039e+08 | Z11: . | AA11: 2306153 | AB11: PT. TIGAKA DISTRINDO PERKASA PHARMA | AC11: ELLY HENDRA | AD11: 35 | AE11: 0 | AF11: 966 | AG11: TCNP | AH11: TRA COL NAT POWDER | AJ11: . | AK11: T | AL11: Non-Affiliate | AM11: Distributor | AN11: =VLOOKUP(I11,Sheet1!A:D,4,) -> A320400 | AP11: Invoaice di kasih sore jam pulang kerja jam 17:38.invoaice tanggal 2,10/1/25. MB terima di tanggal 17/1/25. Cortexnya masih belum bisa.
A12: 45658 | B12: Invoiced | C12: SO | D12: 25707911 | E12: 24106387 | F12: 241100250 | G12: 45659 | H12: PT. TIGAKA DISTRINDO PERKASA PHARMA | I12: 409541-0010 | J12: RUBY RED P-WS | K12: 600 | L12: KG | M12: 600 | N12: 698810.88 | O12: 419286528 | P12: 419286528 | Q12: 0 | R12: 0 | S12: IDR | T12: 2.5567846e+08 | U12: 2.5567846e+08 | V12: 1.6360806e+08 | W12: 0.39020587 | X12: 1.6360806e+08 | Z12: . | AA12: 2306153 | AB12: PT. TIGAKA DISTRINDO PERKASA PHARMA | AC12: ELLY HENDRA | AD12: 35 | AE12: 0 | AF12: 960 | AH12: . | AJ12: . | AK12: T | AL12: Non-Affiliate | AM12: Distributor | AN12: =VLOOKUP(I12,Sheet1!A:D,4,) -> A320400 | AP12: Invoaice di kasih sore jam pulang kerja jam 17:38.invoaice tanggal 2,10/1/25. MB terima di tanggal 17/1/25. Cortexnya masih belum bisa.
A13: 45658 | B13: Invoiced | C13: SO | D13: 25707912 | E13: 24106404 | F13: 241200189 | G13: 45659 | H13: PT. TIGAKA DISTRINDO PERKASA JAKARTA | I13: 503651.010 | J13: HICKORY BROWN L-WS | K13: 80 | L13: KG | M13: 80 | N13: 496676.77 | O13: 39734142 | P13: 39734142 | Q13: 0 | R13: 0 | S13: IDR | T13: 14470469 | U13: 14470469 | V13: 25263673 | W13: 0.63581776 | X13: 25263673 | Y13: DEL | Z13: Delivered | AA13: 15159 | AB13: PT. TIGAKA DISTRINDO PERKASA CIKARANG | AC13: ELLY HENDRA | AD13: 35 | AE13: 0 | AF13: 966 | AG13: TCNL | AH13: TRA COL NAT LIQUID | AJ13: . | AK13: T | AL13: Non-Affiliate | AM13: Distributor | AN13: =VLOOKUP(I13,Sheet1!A:D,4,) -> A320400 | AP13: Invoaice di kasih sore jam pulang kerja jam 17:38.invoaice tanggal 2,10/1/25. MB terima di tanggal 17/1/25. Cortexnya masih belum bisa.
A14: 45658 | B14: Invoiced | C14: SO | D14: 25707913 | E14: 24106451 | F14: 241100279 | G14: 45659 | H14: PT. TIGAKA DISTRINDO PERKASA PHARMA | I14: 503651.010 | J14: HICKORY BROWN L-WS | K14: 200 | L14: KG | M14: 200 | N14: 504485.63 | O14: 100897126 | P14: 100897126 | Q14: 0 | R14: 0 | S14: IDR | T14: 36176171 | U14: 36176171 | V14: 64720955 | W14: 0.64145489 | X14: 64720955 | Z14: . | AA14: 2306153 | AB14: PT. TIGAKA DISTRINDO PERKASA PHARMA | AC14: ELLY HENDRA | AD14: 35 | AE14: 0 | AF14: 966 | AG14: TCNL | AH14: TRA COL NAT LIQUID | AJ14: . | AK14: T | AL14: Non-Affiliate | AM14: Distributor | AN14: =VLOOKUP(I14,Sheet1!A:D,4,) -> A320400 | AP14: Invoaice di kasih sore jam pulang kerja jam 17:38.invoaice tanggal 2,10/1/25. MB terima di tanggal 17/1/25. Cortexnya masih belum bisa.
A15: 45658 | B15: Invoiced | C15: SO | D15: 25707914 | E15: 24106478 | F15: 241200218 | G15: 45659 | H15: PT. TIGAKA DISTRINDO PERKASA JAKARTA | I15: 979007.001 | J15: MINT GREEN 97P-WS 1KG | K15: 3 | L15: KG | M15: 3 | N15: 10434182 | O15: 31302547 | P15: 31302547 | Q15: 0 | R15: 0 | S15: IDR | T15: 19437844 | U15: 19437844 | V15: 11864703 | W15: 0.37903314 | X15: 11864703 | Y15: DEL | Z15: Delivered | AA15: 15159 | AB15: PT. TIGAKA DISTRINDO PERKASA CIKARANG | AC15: ELLY HENDRA | AD15: 35 | AE15: 0 | AF15: 966 | AH15: . | AJ15: . | AK15: T | AL15: Non-Affiliate | AM15: Distributor | AN15: =VLOOKUP(I15,Sheet1!A:D,4,) -> A320400 | AP15: Invoaice di kasih sore jam pulang kerja jam 17:38.invoaice tanggal 2,10/1/25. MB terima di tanggal 17/1/25. Cortexnya masih belum bisa.
A16: 45658 | B16: Invoiced | C16: SO | D16: 25707915 | E16: 24106481 | F16: 241100295 | G16: 45659 | H16: PT. TIGAKA DISTRINDO PERKASA PHARMA | I16: 503651.010 | J16: HICKORY BROWN L-WS | K16: 40 | L16: KG | M16: 40 | N16: 504485.63 | O16: 20179425 | P16: 20179425 | Q16: 0 | R16: 0 | S16: IDR | T16: 7235234.3 | U16: 7235234.3 | V16: 12944191 | W16: 0.64145489 | X16: 12944191 | Z16: . | AA16: 2306153 | AB16: PT. TIGAKA DISTRINDO PERKASA PHARMA | AC16: ELLY HENDRA | AD16: 35 | AE16: 0 | AF16: 966 | AG16: TCNL | AH16: TRA COL NAT LIQUID | AJ16: . | AK16: T | AL16: Non-Affiliate | AM16: Distributor | AN16: =VLOOKUP(I16,Sheet1!A:D,4,) -> A320400 | AP16: Invoaice di kasih sore jam pulang kerja jam 17:38.invoaice tanggal 2,10/1/25. MB terima di tanggal 17/1/25. Cortexnya masih belum bisa.
A17: 45658 | B17: Invoiced | C17: SO | D17: 25707916 | E17: 24106497 | F17: 241200225 | G17: 45659 | H17: PT. TIGAKA DISTRINDO PERKASA JAKARTA -HI | I17: 03509A014 | J17: PEACH ORANGE 13.5KG | K17: 54 | L17: KG | M17: 54 | N17: 889177.2 | O17: 48015569 | P17: 48015569 | Q17: 0 | R17: 0 | S17: IDR | T17: 25437202 | U17: 25437202 | V17: 22578366 | W17: 0.47023011 | X17: 22578366 | Z17: . | AA17: 2306392 | AB17: PT. TIGAKA DISTRINDO PERKASA CIKARANG-HI | AC17: Handy Inarto | AD17: 104 | AE17: 0 | AF17: 966 | AH17: . | AJ17: . | AK17: T | AL17: Non-Affiliate | AM17: Distributor | AN17: =VLOOKUP(I17,Sheet1!A:D,4,) -> A320400 | AP17: Invoaice di kasih sore jam pulang kerja jam 17:38.invoaice tanggal 2,10/1/25. MB terima di tanggal 17/1/25. Cortexnya masih belum bisa.
A18: 45658 | B18: Invoiced | C18: SO | D18: 25707917 | E18: 24106498 | F18: 241200226 | G18: 45659 | H18: PT. TIGAKA DISTRINDO PERKASA JAKARTA -HI | I18: 03509A014 | J18: PEACH ORANGE 13.5KG | K18: 54 | L18: KG | M18: 54 | N18: 879817.44 | O18: 47510142 | P18: 47510142 | Q18: 0 | R18: 0 | S18: IDR | T18: 25437202 | U18: 25437202 | V18: 22072939 | W18: 0.46459426 | X18: 22072939 | Z18: . | AA18: 2306392 | AB18: PT. TIGAKA DISTRINDO PERKASA CIKARANG-HI | AC18: Handy Inarto | AD18: 104 | AE18: 0 | AF18: 966 | AH18: . | AJ18: . | AK18: T | AL18: Non-Affiliate | AM18: Distributor | AN18: =VLOOKUP(I18,Sheet1!A:D,4,) -> A320400 | AP18: Invoaice di kasih sore jam pulang kerja jam 17:38.invoaice tanggal 2,10/1/25. MB terima di tanggal 17/1/25. Cortexnya masih belum bisa.
A19: 45658 | B19: Invoiced | C19: SO | D19: 25707918 | E19: 24106500 | F19: 241200228 | G19: 45659 | H19: PT. TIGAKA DISTRINDO PERKASA JAKARTA -AA | I19: 979007.005 | J19: MINT GREEN 97P-WS 5KG | K19: 15 | L19: KG | M19: 15 | N19: 9178191.3 | O19: 1.3767287e+08 | P19: 1.3767287e+08 | Q19: 0 | R19: 0 | S19: IDR | T19: 95184330 | U19: 95184330 | V19: 42488539 | W19: 0.30861955 | X19: 42488539 | Z19: . | AA19: 2306495 | AB19: PT. TIGAKA DISTRINDO PERKASA CIKARANG-AA | AC19: AGNESYA ADIFILIA | AD19: 94 | AE19: 0 | AF19: 966 | AG19: TCNL | AH19: TRA COL NAT LIQUID | AJ19: . | AK19: T | AL19: Non-Affiliate | AM19: Distributor | AN19: =VLOOKUP(I19,Sheet1!A:D,4,) -> A320400 | AP19: Invoaice di kasih sore jam pulang kerja jam 17:38.invoaice tanggal 2,10/1/25. MB terima di tanggal 17/1/25. Cortexnya masih belum bisa.
A20: 45658 | B20: Invoiced | C20: SO | D20: 25707919 | E20: 24106542 | F20: 241200233 | G20: 45659 | H20: PT. TIGAKA DISTRINDO PERKASA JAKARTA -HI | I20: 979007.001 | J20: MINT GREEN 97P-WS 1KG | K20: 8 | L20: KG | M20: 8 | N20: 9801577.5 | O20: 78412620 | P20: 78412620 | Q20: 0 | R20: 0 | S20: IDR | T20: 51834252 | U20: 51834252 | V20: 26578368 | W20: 0.33895523 | X20: 26578368 | Z20: . | AA20: 2306392 | AB20: PT. TIGAKA DISTRINDO PERKASA CIKARANG-HI | AC20: Handy Inarto | AD20: 104 | AE20: 0 | AF20: 966 | AH20: . | AJ20: . | AK20: T | AL20: Non-Affiliate | AM20: Distributor | AN20: =VLOOKUP(I20,Sheet1!A:D,4,) -> A320400 | AP20: Invoaice di kasih sore jam pulang kerja jam 17:38.invoaice tanggal 2,10/1/25. MB terima di tanggal 17/1/25. Cortexnya masih belum bisa.
A21: 45658 | B21: Invoiced | C21: SO | D21: 25707920 | E21: 24106353 | F21: 241100225 | G21: 45667 | H21: PT. TIGAKA DISTRINDO PERKASA PHARMA | I21: 952360010 | J21: PONCEAU 4R LAKE MD 10KG | K21: 300 | L21: KG | M21: 300 | N21: 414064 | O21: 124219200 | P21: 124219200 | Q21: 0 | R21: 0 | S21: IDR | T21: 94383150 | U21: 94383150 | V21: 29836050 | W21: 0.24018871 | X21: 29836050 | Z21: . | AA21: 2306153 | AB21: PT. TIGAKA DISTRINDO PERKASA PHARMA | AC21: ELLY HENDRA | AD21: 35 | AE21: 0 | AF21: 963 | AG21: TCSK | AH21: TRA COL SYN LAKE | AJ21: . | AK21: T | AL21: Non-Affiliate | AM21: Distributor | AN21: =VLOOKUP(I21,Sheet1!A:D,4,) -> A320400 | AP21: Invoaice di kasih sore jam pulang kerja jam 17:38.invoaice tanggal 2,10/1/25. MB terima di tanggal 17/1/25. Cortexnya masih belum bisa.
A22: 45658 | B22: Invoiced | C22: SO | D22: 25707921 | E22: 24106394 | F22: 241100257 | G22: 45667 | H22: PT. TIGAKA DISTRINDO PERKASA PHARMA | I22: 909324B10 | J22: EUROLAKE CARMOISINE 10KG | K22: 40 | L22: KG | M22: 40 | N22: 916576.29 | O22: 36663052 | P22: 36663052 | Q22: 0 | R22: 0 | S22: IDR | T22: 15708414 | U22: 15708414 | V22: 20954638 | W22: 0.57154647 | X22: 20954638 | Z22: . | AA22: 2306153 | AB22: PT. TIGAKA DISTRINDO PERKASA PHARMA | AC22: ELLY HENDRA | AD22: 35 | AE22: 0 | AF22: 963 | AG22: TCSK | AH22: TRA COL SYN LAKE | AJ22: . | AK22: T | AL22: Non-Affiliate | AM22: Distributor | AN22: =VLOOKUP(I22,Sheet1!A:D,4,) -> A320400 | AP22: Invoaice di kasih sore jam pulang kerja jam 17:38.invoaice tanggal 2,10/1/25. MB terima di tanggal 17/1/25. Cortexnya masih belum bisa.
A23: 45658 | B23: Invoiced | C23: SO | D23: 25707922 | E23: 24106414 | F23: 241100262 | G23: 45667 | H23: PT. TIGAKA DISTRINDO PERKASA PHARMA | I23: 097331001 | J23: FD&C YELLOW 5 ALLK 14-16% 1KG | K23: 14 | L23: KG | M23: 14 | N23: 2440321.1 | O23: 34164496 | P23: 34164496 | Q23: 0 | R23: 0 | S23: IDR | T23: 7027874.3 | U23: 7027874.3 | V23: 27136622 | W23: 0.79429305 | X23: 27136622 | Z23: . | AA23: 2306153 | AB23: PT. TIGAKA DISTRINDO PERKASA PHARMA | AC23: ELLY HENDRA | AD23: 35 | AE23: 0 | AF23: 963 | AG23: TCSK | AH23: TRA COL SYN LAKE | AJ23: . | AK23: T | AL23: Non-Affiliate | AM23: Distributor | AN23: =VLOOKUP(I23,Sheet1!A:D,4,) -> A320400 | AP23: Invoaice di kasih sore jam pulang kerja jam 17:38.invoaice tanggal 2,10/1/25. MB terima di tanggal 17/1/25. Cortexnya masih belum bisa.
A24: 45658 | B24: Invoiced | C24: SO | D24: 25707923 | E24: 24106422 | F24: 241100269 | G24: 45667 | H24: PT. TIGAKA DISTRINDO PERKASA PHARMA | I24: 097331001 | J24: FD&C YELLOW 5 ALLK 14-16% 1KG | K24: 6 | L24: KG | M24: 6 | N24: 2440321.1 | O24: 14641927 | P24: 14641927 | Q24: 0 | R24: 0 | S24: IDR | T24: 3011946.1 | U24: 3011946.1 | V24: 11629981 | W24: 0.79429305 | X24: 11629981 | Z24: . | AA24: 2306153 | AB24: PT. TIGAKA DISTRINDO PERKASA PHARMA | AC24: ELLY HENDRA | AD24: 35 | AE24: 0 | AF24: 963 | AG24: TCSK | AH24: TRA COL SYN LAKE | AJ24: . | AK24: T | AL24: Non-Affiliate | AM24: Distributor | AN24: =VLOOKUP(I24,Sheet1!A:D,4,) -> A320400 | AP24: Invoaice di kasih sore jam pulang kerja jam 17:38.invoaice tanggal 2,10/1/25. MB terima di tanggal 17/1/25. Cortexnya masih belum bisa.
A25: 45658 | B25: Invoiced | C25: SO | D25: 25707924 | E25: 24106472 | F25: 241200215 | G25: 45667 | H25: PT. TIGAKA DISTRINDO PERKASA JAKARTA -HI | I25: 091451020 | J25: BROWN LAKE BLEND R | K25: 40 | L25: KG | M25: 40 | N25: 1290582.2 | O25: 51623290 | P25: 51623290 | Q25: 0 | R25: 0 | S25: IDR | T25: 28066874 | U25: 28066874 | V25: 23556416 | W25: 0.45631373 | X25: 23556416 | Z25: . | AA25: 2306392 | AB25: PT. TIGAKA DISTRINDO PERKASA CIKARANG-HI | AC25: Handy Inarto | AD25: 104 | AE25: 0 | AF25: 960 | AH25: . | AJ25: . | AK25: T | AL25: Non-Affiliate | AM25: Distributor | AN25: =VLOOKUP(I25,Sheet1!A:D,4,) -> A320400 | AP25: Invoaice di kasih sore jam pulang kerja jam 17:38.invoaice tanggal 2,10/1/25. MB terima di tanggal 17/1/25. Cortexnya masih belum bisa.
A26: 45658 | B26: Invoiced | C26: SO | D26: 25707925 | E26: 24106482 | F26: 241200219 | G26: 45667 | H26: PT. TIGAKA DISTRINDO PERKASA JAKARTA | I26: 036431020 | J26: BERRY MICROFINE 20KG | K26: 40 | L26: KG | M26: 40 | N26: 739372.65 | O26: 29574906 | P26: 29574906 | Q26: 0 | R26: 0 | S26: IDR | T26: 21789983 | U26: 21789983 | V26: 7784923.3 | W26: 0.26322732 | X26: 7784923.3 | Y26: DEL | Z26: Delivered | AA26: 15159 | AB26: PT. TIGAKA DISTRINDO PERKASA CIKARANG | AC26: ELLY HENDRA | AD26: 35 | AE26: 0 | AF26: 960 | AH26: . | AJ26: . | AK26: T | AL26: Non-Affiliate | AM26: Distributor | AN26: =VLOOKUP(I26,Sheet1!A:D,4,) -> A320400 | AP26: Invoaice di kasih sore jam pulang kerja jam 17:38.invoaice tanggal 2,10/1/25. MB terima di tanggal 17/1/25. Cortexnya masih belum bisa.
A27: 45658 | B27: Invoiced | C27: SO | D27: 25707926 | E27: 24106486 | F27: 241200221 | G27: 45667 | H27: PT. TIGAKA DISTRINDO PERKASA JAKARTA | I27: 97CB0935 | J27: CM RED 500CPWD | K27: 10 | L27: KG | M27: 10 | N27: 6944461.5 | O27: 69444615 | P27: 69444615 | Q27: 0 | R27: 0 | S27: IDR | T27: 71648053 | U27: 71648053 | V27: -2203437.6 | W27: -0.031729424 | X27: -2203437.6 | Y27: DEL | Z27: Delivered | AA27: 15159 | AB27: PT. TIGAKA DISTRINDO PERKASA CIKARANG | AC27: ELLY HENDRA | AD27: 35 | AE27: 0 | AF27: 966 | AG27: TCSB | AH27: TRA COL SYN DYE POWDER BLEND | AJ27: . | AK27: T | AL27: Non-Affiliate | AM27: Distributor | AN27: =VLOOKUP(I27,Sheet1!A:D,4,) -> A320400 | AP27: Invoaice di kasih sore jam pulang kerja jam 17:38.invoaice tanggal 2,10/1/25. MB terima di tanggal 17/1/25. Cortexnya masih belum bisa.
A28: 45658 | B28: Invoiced | C28: SO | D28: 25707927 | E28: 24106528 | F28: 241200229 | G28: 45667 | H28: PT. TIGAKA DISTRINDO PERKASA JAKARTA -AA | I28: T230104 | J28: EUROBLEND GREEN 973 | K28: 75 | L28: KG | M28: 75 | N28: 568857.3 | O28: 42664298 | P28: 42664298 | Q28: 0 | R28: 0 | S28: IDR | T28: 26080628 | U28: 26080628 | V28: 16583669 | W28: 0.38870133 | X28: 16583669 | Z28: . | AA28: 2306495 | AB28: PT. TIGAKA DISTRINDO PERKASA CIKARANG-AA | AC28: AGNESYA ADIFILIA | AD28: 94 | AE28: 0 | AF28: 960 | AH28: . | AJ28: . | AK28: T | AL28: Non-Affiliate | AM28: Distributor | AN28: =VLOOKUP(I28,Sheet1!A:D,4,) -> A320400 | AP28: Invoaice di kasih sore jam pulang kerja jam 17:38.invoaice tanggal 2,10/1/25. MB terima di tanggal 17/1/25. Cortexnya masih belum bisa.
A29: 45658 | B29: Invoiced | C29: SO | D29: 25707941 | E29: 24106353 | F29: 241100225 | G29: 45659 | H29: PT. TIGAKA DISTRINDO PERKASA PHARMA | I29: 077001020 | J29: FD&C RED NO.40 POWDER 20KG | K29: 180 | L29: KG | M29: 180 | N29: 860427.52 | O29: 1.5487695e+08 | P29: 1.5487695e+08 | Q29: 0 | R29: 0 | S29: IDR | T29: 43091069 | U29: 43091069 | V29: 1.1178588e+08 | W29: 0.72177223 | X29: 1.1178588e+08 | Z29: . | AA29: 2306153 | AB29: PT. TIGAKA DISTRINDO PERKASA PHARMA | AC29: ELLY HENDRA | AD29: 35 | AE29: 0 | AF29: 961 | AG29: TCSP | AH29: TRA COL SYN DYE POWDER | AJ29: . | AK29: T | AL29: Non-Affiliate | AM29: Distributor | AN29: =VLOOKUP(I29,Sheet1!A:D,4,) -> A320400 | AP29: Invoice dikasih jam 09:30. invoice tanggal 2,10,14,17/1/25. MB terima di tanggal 23/1/25.
A30: 45658 | B30: Invoiced | C30: SO | D30: 25707942 | E30: 24106393 | F30: 241100256 | G30: 45659 | H30: PT. TIGAKA DISTRINDO PERKASA PHARMA | I30: 030131005 | J30: BETA CAROTENE ORANGE P 10% 5KG | K30: 5 | L30: KG | M30: 5 | N30: 4207423.8 | O30: 21037119 | P30: 21037119 | Q30: 0 | R30: 0 | S30: IDR | T30: 15728978 | U30: 15728978 | V30: 5308141.1 | W30: 0.25232262 | X30: 5308141.1 | Z30: . | AA30: 2306153 | AB30: PT. TIGAKA DISTRINDO PERKASA PHARMA | AC30: ELLY HENDRA | AD30: 35 | AE30: 0 | AF30: 966 | AG30: TCNP | AH30: TRA COL NAT POWDER | AJ30: . | AK30: T | AL30: Non-Affiliate | AM30: Distributor | AN30: =VLOOKUP(I30,Sheet1!A:D,4,) -> A320400 | AP30: Invoice dikasih jam 09:30. invoice tanggal 2,10,14,17/1/25. MB terima di tanggal 23/1/25.
A31: 45658 | B31: Invoiced | C31: SO | D31: 25707943 | E31: 24106387 | F31: 241100250 | G31: 45667 | H31: PT. TIGAKA DISTRINDO PERKASA PHARMA | I31: 036431020 | J31: BERRY MICROFINE 20KG | K31: 120 | L31: KG | M31: 120 | N31: 790453.18 | O31: 94854382 | P31: 94854382 | Q31: 0 | R31: 0 | S31: IDR | T31: 65369948 | U31: 65369948 | V31: 29484434 | W31: 0.31083892 | X31: 29484434 | Z31: . | AA31: 2306153 | AB31: PT. TIGAKA DISTRINDO PERKASA PHARMA | AC31: ELLY HENDRA | AD31: 35 | AE31: 0 | AF31: 960 | AH31: . | AJ31: . | AK31: T | AL31: Non-Affiliate | AM31: Distributor | AN31: =VLOOKUP(I31,Sheet1!A:D,4,) -> A320400 | AP31: Invoice dikasih jam 09:30. invoice tanggal 2,10,14,17/1/25. MB terima di tanggal 23/1/25.
A32: 45658 | B32: Invoiced | C32: SO | D32: 25707944 | E32: 24106447 | F32: 241200205 | G32: 45667 | H32: PT. TIGAKA DISTRINDO PERKASA JAKARTA | I32: 030131005 | J32: BETA CAROTENE ORANGE P 10% 5KG | K32: 5 | L32: KG | M32: 5 | N32: 4185316.2 | O32: 20926581 | P32: 20926581 | Q32: 0 | R32: 0 | S32: IDR | T32: 15728978 | U32: 15728978 | V32: 5197602.7 | W32: 0.24837324 | X32: 5197602.7 | Y32: DEL | Z32: Delivered | AA32: 15159 | AB32: PT. TIGAKA DISTRINDO PERKASA CIKARANG | AC32: ELLY HENDRA | AD32: 35 | AE32: 0 | AF32: 966 | AG32: TCNP | AH32: TRA COL NAT POWDER | AJ32: . | AK32: T | AL32: Non-Affiliate | AM32: Distributor | AN32: =VLOOKUP(I32,Sheet1!A:D,4,) -> A320400 | AP32: Invoice dikasih jam 09:30. invoice tanggal 2,10,14,17/1/25. MB terima di tanggal 23/1/25.
A33: 45658 | B33: Invoiced | C33: SO | D33: 25707945 | E33: 24106474 | F33: 241200216 | G33: 45667 | H33: PT. TIGAKA DISTRINDO PERKASA JAKARTA | I33: 97CA0826 | J33: SPIRULINA DISPERSION OB | K33: 200 | L33: KG | M33: 200 | N33: 1459753.6 | O33: 291950730 | P33: 291950730 | Q33: 0 | R33: 0 | S33: IDR | T33: 2.2329358e+08 | U33: 2.2329358e+08 | V33: 68657148 | W33: 0.2351669 | X33: 68657148 | Y33: DEL | Z33: Delivered | AA33: 15159 | AB33: PT. TIGAKA DISTRINDO PERKASA CIKARANG | AC33: ELLY HENDRA | AD33: 35 | AE33: 0 | AF33: 960 | AH33: . | AJ33: . | AK33: T | AL33: Non-Affiliate | AM33: Distributor | AN33: =VLOOKUP(I33,Sheet1!A:D,4,) -> A320400 | AP33: Invoice dikasih jam 09:30. invoice tanggal 2,10,14,17/1/25. MB terima di tanggal 23/1/25.
A34: 45658 | B34: Invoiced | C34: SO | D34: 25707946 | E34: 25106558 | F34: 251200003 | G34: 45671 | H34: PT. TIGAKA DISTRINDO PERKASA JAKARTA -AA | I34: 979007.001 | J34: MINT GREEN 97P-WS 1KG | K34: 1 | L34: KG | M34: 1 | N34: 10445174 | O34: 10445174 | P34: 10445174 | Q34: 0 | R34: 0 | S34: IDR | T34: 6479281.5 | U34: 6479281.5 | V34: 3965892.5 | W34: 0.37968659 | X34: 3965892.5 | Z34: . | AA34: 2306495 | AB34: PT. TIGAKA DISTRINDO PERKASA CIKARANG-AA | AC34: AGNESYA ADIFILIA | AD34: 94 | AE34: 0 | AF34: 966 | AH34: . | AJ34: . | AK34: T | AL34: Non-Affiliate | AM34: Distributor | AN34: =VLOOKUP(I34,Sheet1!A:D,4,) -> A320400 | AP34: Invoice dikasih jam 09:30. invoice tanggal 2,10,14,17/1/25. MB terima di tanggal 23/1/25.
A35: 45658 | B35: Invoiced | C35: SO | D35: 25707947 | E35: 25106559 | F35: 251200004 | G35: 45671 | H35: PT. TIGAKA DISTRINDO PERKASA JAKARTA | I35: 979007.001 | J35: MINT GREEN 97P-WS 1KG | K35: 1 | L35: KG | M35: 1 | N35: 10751121 | O35: 10751121 | P35: 10751121 | Q35: 0 | R35: 0 | S35: IDR | T35: 6479281.5 | U35: 6479281.5 | V35: 4271839.7 | W35: 0.397339 | X35: 4271839.7 | Y35: DEL | Z35: Delivered | AA35: 15159 | AB35: PT. TIGAKA DISTRINDO PERKASA CIKARANG | AC35: ELLY HENDRA | AD35: 35 | AE35: 0 | AF35: 966 | AH35: . | AJ35: . | AK35: T | AL35: Non-Affiliate | AM35: Distributor | AN35: =VLOOKUP(I35,Sheet1!A:D,4,) -> A320400 | AP35: Invoice dikasih jam 09:30. invoice tanggal 2,10,14,17/1/25. MB terima di tanggal 23/1/25.
A36: 45658 | B36: Invoiced | C36: SO | D36: 25707948 | E36: 25106563 | F36: 251200006 | G36: 45674 | H36: PT. TIGAKA DISTRINDO PERKASA JAKARTA -HI | I36: IC10348 | J36: BRIGHT RED P-WS | K36: 2 | L36: KG | M36: 2 | N36: 2706505.3 | O36: 5413010.6 | P36: 5413010.6 | Q36: 0 | R36: 0 | S36: IDR | T36: 0 | U36: 0 | V36: 5413010.6 | W36: 1 | X36: 5413010.6 | Z36: . | AA36: 2306392 | AB36: PT. TIGAKA DISTRINDO PERKASA CIKARANG-HI | AC36: Handy Inarto | AD36: 104 | AE36: 0 | AF36: 960 | AH36: . | AJ36: . | AK36: T | AL36: Non-Affiliate | AM36: Distributor | AN36: =VLOOKUP(I36,Sheet1!A:D,4,) -> A320400 | AP36: Invoice dikasih jam 09:30. invoice tanggal 2,10,14,17/1/25. MB terima di tanggal 23/1/25.
A37: 45658 | B37: Invoiced | C37: SO | D37: 25707951 | E37: 24106304 | F37: 241200149 | G37: 45680 | H37: PT. TIGAKA DISTRINDO PERKASA JAKARTA | I37: 077001020 | J37: FD&C RED NO.40 POWDER 20KG | K37: 20 | L37: KG | M37: 20 | N37: 457480.42 | O37: 9149608.4 | P37: 9149608.4 | Q37: 0 | R37: 0 | S37: IDR | T37: 4787896.5 | U37: 4787896.5 | V37: 4361711.8 | W37: 0.47671022 | X37: 4361711.8 | Y37: DEL | Z37: Delivered | AA37: 15159 | AB37: PT. TIGAKA DISTRINDO PERKASA CIKARANG | AC37: ELLY HENDRA | AD37: 35 | AE37: 0 | AF37: 961 | AG37: TCSP | AH37: TRA COL SYN DYE POWDER | AJ37: . | AK37: T | AL37: Non-Affiliate | AM37: Distributor | AN37: =VLOOKUP(I37,Sheet1!A:D,4,) -> A320400 | AP37: Invoice di kasih tanggal 28/1/25. Invoice tgl 15,23,24. coratex masih nyoba,MB terima di tanggal 28/1/25. jam 11:08.
A38: 45658 | B38: Invoiced | C38: SO | D38: 25707952 | E38: 24106393 | F38: 241100256 | G38: 45680 | H38: PT. TIGAKA DISTRINDO PERKASA PHARMA | I38: 030131005 | J38: BETA CAROTENE ORANGE P 10% 5KG | K38: 5 | L38: KG | M38: 5 | N38: 4207423.8 | O38: 21037119 | P38: 21037119 | Q38: 0 | R38: 0 | S38: IDR | T38: 15728978 | U38: 15728978 | V38: 5308141.1 | W38: 0.25232262 | X38: 5308141.1 | Z38: . | AA38: 2306153 | AB38: PT. TIGAKA DISTRINDO PERKASA PHARMA | AC38: ELLY HENDRA | AD38: 35 | AE38: 0 | AF38: 966 | AG38: TCNP | AH38: TRA COL NAT POWDER | AJ38: . | AK38: T | AL38: Non-Affiliate | AM38: Distributor | AN38: =VLOOKUP(I38,Sheet1!A:D,4,) -> A320400 | AP38: Invoice di kasih tanggal 28/1/25. Invoice tgl 15,23,24. coratex masih nyoba,MB terima di tanggal 28/1/25. jam 11:08.
A39: 45658 | B39: Invoiced | C39: SO | D39: 25707953 | E39: 24106404 | F39: 241200189 | G39: 45680 | H39: PT. TIGAKA DISTRINDO PERKASA JAKARTA | I39: 503651.010 | J39: HICKORY BROWN L-WS | K39: 40 | L39: KG | M39: 40 | N39: 496676.77 | O39: 19867071 | P39: 19867071 | Q39: 0 | R39: 0 | S39: IDR | T39: 7235234.3 | U39: 7235234.3 | V39: 12631837 | W39: 0.63581776 | X39: 12631837 | Y39: DEL | Z39: Delivered | AA39: 15159 | AB39: PT. TIGAKA DISTRINDO PERKASA CIKARANG | AC39: ELLY HENDRA | AD39: 35 | AE39: 0 | AF39: 966 | AG39: TCNL | AH39: TRA COL NAT LIQUID | AJ39: . | AK39: T | AL39: Non-Affiliate | AM39: Distributor | AN39: =VLOOKUP(I39,Sheet1!A:D,4,) -> A320400 | AP39: Invoice di kasih tanggal 28/1/25. Invoice tgl 15,23,24. coratex masih nyoba,MB terima di tanggal 28/1/25. jam 11:08.
A40: 45658 | B40: Invoiced | C40: SO | D40: 25707954 | E40: 24106454 | F40: 241200209 | G40: 45680 | H40: PT. TIGAKA DISTRINDO PERKASA JAKARTA | I40: 506091C-0013 | J40: FUSION HAZELNUT BROWN L-WS | K40: 13 | L40: KG | M40: 13 | N40: 730500.18 | O40: 9496502.3 | P40: 9496502.3 | Q40: 0 | R40: 0 | S40: IDR | T40: 3426516 | U40: 3426516 | V40: 6069986.3 | W40: 0.63918126 | X40: 6069986.3 | Y40: DEL | Z40: Delivered | AA40: 15159 | AB40: PT. TIGAKA DISTRINDO PERKASA CIKARANG | AC40: ELLY HENDRA | AD40: 35 | AE40: 0 | AF40: 960 | AH40: . | AJ40: . | AK40: T | AL40: Non-Affiliate | AM40: Distributor | AN40: =VLOOKUP(I40,Sheet1!A:D,4,) -> A320400 | AP40: Invoice di kasih tanggal 28/1/25. Invoice tgl 15,23,24. coratex masih nyoba,MB terima di tanggal 28/1/25. jam 11:08.
A41: 45658 | B41: Invoiced | C41: SO | D41: 25707955 | E41: 24106471 | F41: 241200214 | G41: 45680 | H41: PT. TIGAKA DISTRINDO PERKASA JAKARTA | I41: 409050.005 | J41: PAPRIKA EXT 20000 CU L-WS 5KG | K41: 25 | L41: KG | M41: 25 | N41: 1452750.5 | O41: 36318763 | P41: 36318763 | Q41: 0 | R41: 0 | S41: IDR | T41: 8948520.5 | U41: 8948520.5 | V41: 27370242 | W41: 0.75361164 | X41: 27370242 | Y41: DEL | Z41: Delivered | AA41: 15159 | AB41: PT. TIGAKA DISTRINDO PERKASA CIKARANG | AC41: ELLY HENDRA | AD41: 35 | AE41: 0 | AF41: 966 | AG41: TCNL | AH41: TRA COL NAT LIQUID | AJ41: . | AK41: T | AL41: Non-Affiliate | AM41: Distributor | AN41: =VLOOKUP(I41,Sheet1!A:D,4,) -> A320400 | AP41: Invoice di kasih tanggal 28/1/25. Invoice tgl 15,23,24. coratex masih nyoba,MB terima di tanggal 28/1/25. jam 11:08.
A42: 45658 | B42: Invoiced | C42: SO | D42: 25707956 | E42: 24106495 | F42: 241100301 | G42: 45680 | H42: PT. TIGAKA DISTRINDO PERKASA PHARMA | I42: 503651.010 | J42: HICKORY BROWN L-WS | K42: 140 | L42: KG | M42: 140 | N42: 512722.96 | O42: 71781214 | P42: 71781214 | Q42: 0 | R42: 0 | S42: IDR | T42: 25323320 | U42: 25323320 | V42: 46457894 | W42: 0.64721522 | X42: 46457894 | Z42: . | AA42: 2306153 | AB42: PT. TIGAKA DISTRINDO PERKASA PHARMA | AC42: ELLY HENDRA | AD42: 35 | AE42: 0 | AF42: 966 | AG42: TCNL | AH42: TRA COL NAT LIQUID | AJ42: . | AK42: T | AL42: Non-Affiliate | AM42: Distributor | AN42: =VLOOKUP(I42,Sheet1!A:D,4,) -> A320400 | AP42: Invoice di kasih tanggal 28/1/25. Invoice tgl 15,23,24. coratex masih nyoba,MB terima di tanggal 28/1/25. jam 11:08.
A43: 45658 | B43: Invoiced | C43: SO | D43: 25707957 | E43: 24106502 | F43: 241100304 | G43: 45680 | H43: PT. TIGAKA DISTRINDO PERKASA PHARMA | I43: 503651.010 | J43: HICKORY BROWN L-WS | K43: 10 | L43: KG | M43: 10 | N43: 512722.96 | O43: 5127229.6 | P43: 5127229.6 | Q43: 0 | R43: 0 | S43: IDR | T43: 1808808.6 | U43: 1808808.6 | V43: 3318421 | W43: 0.64721522 | X43: 3318421 | Z43: . | AA43: 2306153 | AB43: PT. TIGAKA DISTRINDO PERKASA PHARMA | AC43: ELLY HENDRA | AD43: 35 | AE43: 0 | AF43: 966 | AG43: TCNL | AH43: TRA COL NAT LIQUID | AJ43: . | AK43: T | AL43: Non-Affiliate | AM43: Distributor | AN43: =VLOOKUP(I43,Sheet1!A:D,4,) -> A320400 | AP43: Invoice di kasih tanggal 28/1/25. Invoice tgl 15,23,24. coratex masih nyoba,MB terima di tanggal 28/1/25. jam 11:08.
A44: 45658 | B44: Invoiced | C44: SO | D44: 25707958 | E44: 24106528 | F44: 241200229 | G44: 45680 | H44: PT. TIGAKA DISTRINDO PERKASA JAKARTA -AA | I44: 979007.005 | J44: MINT GREEN 97P-WS 5KG | K44: 15 | L44: KG | M44: 15 | N44: 9178191.3 | O44: 1.3767287e+08 | P44: 1.3767287e+08 | Q44: 0 | R44: 0 | S44: IDR | T44: 95184330 | U44: 95184330 | V44: 42488539 | W44: 0.30861955 | X44: 42488539 | Z44: . | AA44: 2306495 | AB44: PT. TIGAKA DISTRINDO PERKASA CIKARANG-AA | AC44: AGNESYA ADIFILIA | AD44: 94 | AE44: 0 | AF44: 966 | AG44: TCNL | AH44: TRA COL NAT LIQUID | AJ44: . | AK44: T | AL44: Non-Affiliate | AM44: Distributor | AN44: =VLOOKUP(I44,Sheet1!A:D,4,) -> A320400 | AP44: Invoice di kasih tanggal 28/1/25. Invoice tgl 15,23,24. coratex masih nyoba,MB terima di tanggal 28/1/25. jam 11:08.
...

Sheet OGAWA
A5: PT. Sensient Technologies Indonesia
A6: Date - Period | B6: StatusType | C6: Order Type | D6: Invoice | E6: Customer Order | F6: Order | G6: Ship Date | H6: Customer Group | I6: Item Number | J6: Item Description | K6: Input Quantity | L6: Input UOM | M6: Total KG | N6: Unit Price | O6: Amount | P6: Amount - Sales and orders Only | Q6: Foreign per unit | R6: Foreign Amount | S6: Currency | T6: StandardCost | U6: StandardCost- Sales and orders Only | V6: Gross Margin | W6: Gross Margin % | X6: Margin - Sales and orders Only | Y6: IncoTerms | Z6: IncoTerms Description | AA6: Ship To | AB6: Ship To Name | AC6: Sales Region Desc | AD6: Sales Region | AE6: Delivery Days | AF6: GL Category | AG6: Cat6 | AH6: Cat 6 Desc | AI6: Cat7 | AJ6: Cat 7 Desc | AK6: SaleType | AL6: AffiliateType | AM6: CustomerType | AN6: HS-Code | AP6: Note Finance MB
A7: 45658 | B7: Invoiced | C7: SO | D7: 25707940 | E7: 24106480 | F7: 025710 | G7: 45660 | H7: PT. OGAWA INDONESIA | I7: 1206750 | J7: LIME EXTRACT SNO C2122 | K7: 1 | L7: KG | M7: 1 | N7: 64242861 | O7: 64242861 | P7: 64242861 | Q7: 0 | R7: 0 | S7: IDR | T7: 34741658 | U7: 34741658 | V7: 29501203 | W7: 0.45921371 | X7: 29501203 | Y7: DEL | Z7: Delivered | AA7: 15447 | AB7: PT. OGAWA INDONESIA | AC7: ELLY HENDRA | AD7: 35 | AE7: 0 | AF7: 208 | AH7: . | AJ7: . | AK7: T | AL7: Non-Affiliate | AM7: Domestic | AN7: =VLOOKUP(I7,Sheet1!A:D,4,FALSE) -> A210600 | AP7: Invoice dikasih jam 09:30. invoice tanggal 3/1/25. MB terima di tanggal 23/1/25.
A8: 45809 | B8: Invoiced | C8: SO | D8: 25708263 | E8: 25106679 | F8: 026949 | G8: 45812 | H8: PT. OGAWA INDONESIA | I8: 1206750 | J8: LIME EXTRACT SNO C2122 | K8: 0.4 | L8: KG | M8: 0.4 | N8: 91411199 | O8: 36564480 | P8: 36564480 | Q8: 0 | R8: 0 | S8: IDR | T8: 13932796 | U8: 13932796 | V8: 22631684 | W8: 0.61895271 | X8: 22631684 | Y8: DEL | Z8: Delivered | AA8: 15447 | AB8: PT. OGAWA INDONESIA | AC8: AGNESYA ADIFILIA | AD8: 94 | AE8: 0 | AF8: 208 | AH8: . | AJ8: . | AK8: T | AL8: Non-Affiliate | AM8: Domestic | AN8: =VLOOKUP(I8,Sheet1!A:D,4,FALSE) -> A210600 | AP8: Invoice dikasih jam 14:00. invoice tgl 3/6/25. Finance abis Clossing,mB terima di tgl 9/6/25.
A9: 45901 | B9: Invoiced | C9: SO | D9: 25708561 | E9: 25106874 | F9: 028122 | G9: 45923 | H9: PT. OGAWA INDONESIA | I9: 1008421740 | J9: TERPENELESS LEMON EXTRACT 0.9 | K9: 1.8 | L9: KG | M9: 1.8 | N9: 25408000 | O9: 45734400 | P9: 45734400 | Q9: 0 | R9: 0 | S9: IDR | T9: 22772653 | U9: 22772653 | V9: 22961747 | W9: 0.50206732 | X9: 22961747 | Y9: DEL | Z9: Delivered | AA9: 15447 | AB9: PT. OGAWA INDONESIA | AC9: AGNESYA ADIFILIA | AD9: 94 | AE9: 0 | AF9: P208 | AH9: . | AJ9: . | AK9: T | AL9: Non-Affiliate | AM9: Domestic | AN9: =VLOOKUP(I9,Sheet1!A:D,4,FALSE) -> A210600 | AP9: Invoice dikasih siang pas jam makan siang. Invoice tgl 20,23,24/09/2025. MB terima ditanggal 26/9/25.
AN10: =VLOOKUP(I10,Sheet1!A:D,4,FALSE) -> #N/A
AN11: =VLOOKUP(I11,Sheet1!A:D,4,FALSE) -> #N/A
AN12: =VLOOKUP(I12,Sheet1!A:D,4,FALSE) -> #N/A
AN13: =VLOOKUP(I13,Sheet1!A:D,4,FALSE) -> #N/A
AN14: =VLOOKUP(I14,Sheet1!A:D,4,FALSE) -> #N/A
AN15: =VLOOKUP(I15,Sheet1!A:D,4,FALSE) -> #N/A
AN16: =VLOOKUP(I16,Sheet1!A:D,4,FALSE) -> #N/A
AN17: =VLOOKUP(I17,Sheet1!A:D,4,FALSE) -> #N/A
AN18: =VLOOKUP(I18,Sheet1!A:D,4,FALSE) -> #N/A
AN19: =VLOOKUP(I19,Sheet1!A:D,4,FALSE) -> #N/A
AN20: =VLOOKUP(I20,Sheet1!A:D,4,FALSE) -> #N/A
AN21: =VLOOKUP(I21,Sheet1!A:D,4,FALSE) -> #N/A
... AN233: =VLOOKUP(I233,Sheet1!A:D,4,FALSE) -> #N/A

Sheet GMC
A5: PT. Sensient Technologies Indonesia
A6: Date - Period | B6: StatusType | C6: Order Type | D6: Invoice | E6: Customer Order | F6: Order | G6: Ship Date | H6: Customer Group | I6: Item Number | J6: Item Description | K6: Input Quantity | L6: Input UOM | M6: Total KG | N6: Unit Price | O6: Amount | P6: Amount - Sales and orders Only | Q6: Foreign per unit | R6: Foreign Amount | S6: Currency | T6: StandardCost | U6: StandardCost- Sales and orders Only | V6: Gross Margin | W6: Gross Margin % | X6: Margin - Sales and orders Only | Y6: IncoTerms | Z6: IncoTerms Description | AA6: Ship To | AB6: Ship To Name | AC6: Sales Region Desc | AD6: Sales Region | AE6: Delivery Days | AF6: GL Category | AG6: Cat6 | AH6: Cat 6 Desc | AI6: Cat7 | AJ6: Cat 7 Desc | AK6: SaleType | AL6: AffiliateType | AM6: CustomerType | AN6: HS-Code | AP6: Note Finance MB
A7: 45658 | B7: Invoiced | C7: SO | D7: 25707900 | E7: 24106537 | F7: POPD/GMC/24120465 | G7: 45659 | H7: PT. GRAND MULTI CHEMICALS JAKARTA | I7: IDF2004 | J7: DB XF1591 10KG | K7: 40 | L7: KG | M7: 40 | N7: 226225 | O7: 9049000 | P7: 9049000 | Q7: 0 | R7: 0 | S7: IDR | T7: 5684526.9 | U7: 5684526.9 | V7: 3364473.1 | W7: 0.37180607 | X7: 3364473.1 | Y7: DEL | Z7: Delivered | AA7: 15161 | AB7: PT. GRAND MULTI CHEMICALS TANGERANG | AC7: ELLY HENDRA | AD7: 35 | AE7: 0 | AF7: 202 | AH7: . | AJ7: . | AK7: M | AL7: Non-Affiliate | AM7: Distributor | AN7: =VLOOKUP(I7,Sheet1!A:D,4,FALSE) -> A210600 | AP7: Invoice di kasih Tanggal 15/01/25.baru bisa karena Tax Cortex n di seetting sama IT. Invoice tgl 2/1/25.MB terima di tanggal 15/01/25 jam 16:48
A8: 45658 | B8: Invoiced | C8: SO | D8: 25707901 | E8: 24106294 | F8: POPD/GMC/24070273 | G8: 45659 | H8: PT. GRAND MULTI CHEMICALS JAKARTA | I8: IDF2017 | J8: DB N2945 (FML10) 10KG | K8: 900 | L8: KG | M8: 900 | N8: 310898.82 | O8: 279808938 | P8: 279808938 | Q8: 0 | R8: 0 | S8: IDR | T8: 1.4457609e+08 | U8: 1.4457609e+08 | V8: 1.3523285e+08 | W8: 0.48330425 | X8: 1.3523285e+08 | Y8: DEL | Z8: Delivered | AA8: 15161 | AB8: PT. GRAND MULTI CHEMICALS TANGERANG | AC8: ELLY HENDRA | AD8: 35 | AE8: 0 | AF8: 202 | AH8: . | AJ8: . | AK8: M | AL8: Non-Affiliate | AM8: Distributor | AN8: =VLOOKUP(I8,Sheet1!A:D,4,FALSE) -> A210600 | AP8: Invoice di kasih Tanggal 15/01/25.baru bisa karena Tax Cortex n di seetting sama IT. Invoice tgl 2/1/25.MB terima di tanggal 15/01/25 jam 16:48
A9: 45658 | B9: Invoiced | C9: SO | D9: 25707902 | E9: 24106469 | F9: POPD/GMC/24110404 | G9: 45665 | H9: PT. GRAND MULTI CHEMICALS JAKARTA | I9: IDF2016 | J9: DB XF1745 10KG | K9: 760 | L9: KG | M9: 760 | N9: 309447 | O9: 235179720 | P9: 235179720 | Q9: 0 | R9: 0 | S9: IDR | T9: 1.1276695e+08 | U9: 1.1276695e+08 | V9: 1.2241277e+08 | W9: 0.52050733 | X9: 1.2241277e+08 | Y9: DEL | Z9: Delivered | AA9: 15161 | AB9: PT. GRAND MULTI CHEMICALS TANGERANG | AC9: ELLY HENDRA | AD9: 35 | AE9: 0 | AF9: 202 | AH9: . | AJ9: . | AK9: M | AL9: Non-Affiliate | AM9: Distributor | AN9: =VLOOKUP(I9,Sheet1!A:D,4,FALSE) -> A210600 | AP9: Invoice di kasih Tanggal 15/01/25.baru bisa karena Tax Cortex n di seetting sama IT. Invoice tgl 2/1/25.MB terima di tanggal 15/01/25 jam 16:48
A10: 45658 | B10: Invoiced | C10: SO | D10: 25707903 | E10: 24106487 | F10: POPD/GMC/24120418 | G10: 45665 | H10: PT. GRAND MULTI CHEMICALS JAKARTA | I10: IDF2005 | J10: DB XF1951 10KG | K10: 430 | L10: KG | M10: 430 | N10: 255491.39 | O10: 1.098613e+08 | P10: 1.098613e+08 | Q10: 0 | R10: 0 | S10: IDR | T10: 58649689 | U10: 58649689 | V10: 51211608 | W10: 0.46614786 | X10: 51211608 | Y10: DEL | Z10: Delivered | AA10: 15161 | AB10: PT. GRAND MULTI CHEMICALS TANGERANG | AC10: ELLY HENDRA | AD10: 35 | AE10: 0 | AF10: 202 | AH10: . | AJ10: . | AK10: M | AL10: Non-Affiliate | AM10: Distributor | AN10: =VLOOKUP(I10,Sheet1!A:D,4,FALSE) -> A210600 | AP10: Invoice di kasih Tanggal 15/01/25.baru bisa karena Tax Cortex n di seetting sama IT. Invoice tgl 2/1/25.MB terima di tanggal 15/01/25 jam 16:48
A11: 45658 | B11: Invoiced | C11: SO | D11: 25707904 | E11: 24106491 | F11: POPD/GMC/24120432 | G11: 45665 | H11: PT. GRAND MULTI CHEMICALS JAKARTA | I11: 9624950020 | J11: DAIRYBOOST BUTTER FLVR 20KG *A | K11: 20 | L11: KG | M11: 20 | N11: 913599.23 | O11: 18271985 | P11: 18271985 | Q11: 0 | R11: 0 | S11: IDR | T11: 11596533 | U11: 11596533 | V11: 6675451.8 | W11: 0.36533808 | X11: 6675451.8 | Y11: DEL | Z11: Delivered | AA11: 15161 | AB11: PT. GRAND MULTI CHEMICALS TANGERANG | AC11: ELLY HENDRA | AD11: 35 | AE11: 0 | AF11: 208 | AH11: . | AJ11: . | AK11: T | AL11: Non-Affiliate | AM11: Distributor | AN11: =VLOOKUP(I11,Sheet1!A:D,4,FALSE) -> A210600 | AP11: Invoice di kasih Tanggal 15/01/25.baru bisa karena Tax Cortex n di seetting sama IT. Invoice tgl 2/1/25.MB terima di tanggal 15/01/25 jam 16:48
A12: 45658 | B12: Invoiced | C12: SO | D12: 25707905 | E12: 24106490 | F12: POPD/GMC/24120431 | G12: 45665 | H12: PT. GRAND MULTI CHEMICALS JAKARTA-AA | I12: 9637050025 | J12: SWEETEASE 3G FLAV N11839 25KG | K12: 100 | L12: KG | M12: 100 | N12: 490110 | O12: 49011000 | P12: 49011000 | Q12: 0 | R12: 0 | S12: IDR | T12: 32069577 | U12: 32069577 | V12: 16941423 | W12: 0.34566572 | X12: 16941423 | Z12: . | AA12: 2306511 | AB12: PT. GRAND MULTI CHEMICALS TANGERANG-AA | AC12: AGNESYA ADIFILIA | AD12: 94 | AE12: 0 | AF12: 101 | AH12: . | AJ12: . | AK12: T | AL12: Non-Affiliate | AM12: Distributor | AN12: =VLOOKUP(I12,Sheet1!A:D,4,FALSE) -> A210600 | AP12: Invoice di kasih tanggal 17/1/25. invoice tanggal 8 & 14/01/25.MB terima di tanggal 17/1/25. Cortexnya masih belum bisa.
A13: 45658 | B13: Invoiced | C13: SO | D13: 25707906 | E13: 25106543 | F13: POPD/GMC/25010008 | G13: 45665 | H13: PT. GRAND MULTI CHEMICALS JAKARTA-AA | I13: 96393200.25 | J13: LVR024 | K13: 25 | L13: KG | M13: 25 | N13: 483097 | O13: 12077425 | P13: 12077425 | Q13: 0 | R13: 0 | S13: IDR | T13: 9715618.2 | U13: 9715618.2 | V13: 2361806.8 | W13: 0.1955555 | X13: 2361806.8 | Z13: . | AA13: 2306511 | AB13: PT. GRAND MULTI CHEMICALS TANGERANG-AA | AC13: AGNESYA ADIFILIA | AD13: 94 | AE13: 0 | AF13: 208 | AH13: . | AJ13: . | AK13: T | AL13: Non-Affiliate | AM13: Distributor | AN13: =VLOOKUP(I13,Sheet1!A:D,4,FALSE) -> A210600 | AP13: Invoice di kasih tanggal 17/1/25. invoice tanggal 8 & 14/01/25.MB terima di tanggal 17/1/25. Cortexnya masih belum bisa.
A14: 45658 | B14: Invoiced | C14: SO | D14: 25707907 | E14: 24106494 | F14: POPD/GMC/24120437 | G14: 45671 | H14: PT. GRAND MULTI CHEMICALS JAKARTA-AA | I14: IF2576 | J14: SPEARMINT FLAVOUR | K14: 50 | L14: KG | M14: 50 | N14: 842434.92 | O14: 42121746 | P14: 42121746 | Q14: 0 | R14: 0 | S14: IDR | T14: 24011384 | U14: 24011384 | V14: 18110362 | W14: 0.42995279 | X14: 18110362 | Z14: . | AA14: 2306511 | AB14: PT. GRAND MULTI CHEMICALS TANGERANG-AA | AC14: AGNESYA ADIFILIA | AD14: 94 | AE14: 0 | AF14: 208 | AH14: . | AJ14: . | AK14: T | AL14: Non-Affiliate | AM14: Distributor | AN14: =VLOOKUP(I14,Sheet1!A:D,4,FALSE) -> A210600 | AP14: Invoice di kasih tanggal 17/1/25. invoice tanggal 8 & 14/01/25.MB terima di tanggal 17/1/25. Cortexnya masih belum bisa.
A15: 45689 | B15: Invoiced | C15: SO | D15: 25707979 | E15: 25106570 | F15: POPD/GMC/25010028 | G15: 45691 | H15: PT. GRAND MULTI CHEMICALS JAKARTA | I15: IDF2003 | J15: DB XF1589 10KG | K15: 300 | L15: KG | M15: 300 | N15: 304251.29 | O15: 91275387 | P15: 91275387 | Q15: 0 | R15: 0 | S15: IDR | T15: 48849983 | U15: 48849983 | V15: 42425404 | W15: 0.46480662 | X15: 42425404 | Y15: DEL | Z15: Delivered | AA15: 15161 | AB15: PT. GRAND MULTI CHEMICALS TANGERANG | AC15: ELLY HENDRA | AD15: 35 | AE15: 0 | AF15: 202 | AH15: . | AJ15: . | AK15: M | AL15: Non-Affiliate | AM15: Distributor | AN15: =VLOOKUP(I15,Sheet1!A:D,4,FALSE) -> A210600 | AP15: Invoice dikasih sore jam 15:30.Invoice tanggal 03/02/2025,MB terima di tanggal 10/2/25.
A16: 45689 | B16: Invoiced | C16: SO | D16: 25707980 | E16: 24106464 | F16: POPD/GMC/24110399 | G16: 45691 | H16: PT. GRAND MULTI CHEMICALS JAKARTA | I16: IDF5028 | J16: HONEY FLAVOR | K16: 500 | L16: KG | M16: 500 | N16: 288744.48 | O16: 144372240 | P16: 144372240 | Q16: 0 | R16: 0 | S16: IDR | T16: 1.1579444e+08 | U16: 1.1579444e+08 | V16: 28577802 | W16: 0.19794527 | X16: 28577802 | Y16: DEL | Z16: Delivered | AA16: 15161 | AB16: PT. GRAND MULTI CHEMICALS TANGERANG | AC16: ELLY HENDRA | AD16: 35 | AE16: 0 | AF16: 102 | AH16: . | AJ16: . | AK16: M | AL16: Non-Affiliate | AM16: Distributor | AN16: =VLOOKUP(I16,Sheet1!A:D,4,FALSE) -> A210600 | AP16: Invoice dikasih sore jam 15:30.Invoice tanggal 03/02/2025,MB terima di tanggal 10/2/25.
A17: 45689 | B17: Invoiced | C17: SO | D17: 25707981 | E17: 24106487 | F17: POPD/GMC/24120418 | G17: 45691 | H17: PT. GRAND MULTI CHEMICALS JAKARTA | I17: IDF2005 | J17: DB XF1951 10KG | K17: 250 | L17: KG | M17: 250 | N17: 255491.39 | O17: 63872848 | P17: 63872848 | Q17: 0 | R17: 0 | S17: IDR | T17: 34098657 | U17: 34098657 | V17: 29774191 | W17: 0.46614786 | X17: 29774191 | Y17: DEL | Z17: Delivered | AA17: 15161 | AB17: PT. GRAND MULTI CHEMICALS TANGERANG | AC17: ELLY HENDRA | AD17: 35 | AE17: 0 | AF17: 202 | AH17: . | AJ17: . | AK17: M | AL17: Non-Affiliate | AM17: Distributor | AN17: =VLOOKUP(I17,Sheet1!A:D,4,FALSE) -> A210600 | AP17: Invoice dikasih sore jam 15:30.Invoice tanggal 03/02/2025,MB terima di tanggal 10/2/25.
A18: 45689 | B18: Invoiced | C18: SO | D18: 25707982 | E18: 24106537 | F18: POPD/GMC/24120465 | G18: 45691 | H18: PT. GRAND MULTI CHEMICALS JAKARTA | I18: IDF2004 | J18: DB XF1591 10KG | K18: 960 | L18: KG | M18: 960 | N18: 226225 | O18: 217176000 | P18: 217176000 | Q18: 0 | R18: 0 | S18: IDR | T18: 1.3642865e+08 | U18: 1.3642865e+08 | V18: 80747355 | W18: 0.37180607 | X18: 80747355 | Y18: DEL | Z18: Delivered | AA18: 15161 | AB18: PT. GRAND MULTI CHEMICALS TANGERANG | AC18: ELLY HENDRA | AD18: 35 | AE18: 0 | AF18: 202 | AH18: . | AJ18: . | AK18: M | AL18: Non-Affiliate | AM18: Distributor | AN18: =VLOOKUP(I18,Sheet1!A:D,4,FALSE) -> A210600 | AP18: Invoice dikasih sore jam 15:30.Invoice tanggal 03/02/2025,MB terima di tanggal 10/2/25.
A19: 45689 | B19: Invoiced | C19: SO | D19: 25707983 | E19: 25106572 | F19: POPD/GMC/25010030 | G19: 45691 | H19: PT. GRAND MULTI CHEMICALS JAKARTA | I19: IDF2016 | J19: DB XF1745 10KG | K19: 150 | L19: KG | M19: 150 | N19: 322054.08 | O19: 48308112 | P19: 48308112 | Q19: 0 | R19: 0 | S19: IDR | T19: 22501330 | U19: 22501330 | V19: 25806782 | W19: 0.53421218 | X19: 25806782 | Y19: DEL | Z19: Delivered | AA19: 15161 | AB19: PT. GRAND MULTI CHEMICALS TANGERANG | AC19: ELLY HENDRA | AD19: 35 | AE19: 0 | AF19: 202 | AH19: . | AJ19: . | AK19: M | AL19: Non-Affiliate | AM19: Distributor | AN19: =VLOOKUP(I19,Sheet1!A:D,4,FALSE) -> A210600 | AP19: Invoice dikasih sore jam 15:30.Invoice tanggal 03/02/2025,MB terima di tanggal 10/2/25.
A20: 45689 | B20: Invoiced | C20: SO | D20: 25707987 | E20: 25106569 | F20: POPD/GMC/25010027 | G20: 45691 | H20: PT. GRAND MULTI CHEMICALS JAKARTA-AA | I20: 9637050025 | J20: SWEETEASE 3G FLAV N11839 25KG | K20: 50 | L20: KG | M20: 50 | N20: 505920 | O20: 25296000 | P20: 25296000 | Q20: 0 | R20: 0 | S20: IDR | T20: 16028611 | U20: 16028611 | V20: 9267389.1 | W20: 0.36635789 | X20: 9267389.1 | Z20: . | AA20: 2306511 | AB20: PT. GRAND MULTI CHEMICALS TANGERANG-AA | AC20: AGNESYA ADIFILIA | AD20: 94 | AE20: 0 | AF20: 101 | AH20: . | AJ20: . | AK20: T | AL20: Non-Affiliate | AM20: Distributor | AN20: =VLOOKUP(I20,Sheet1!A:D,4,FALSE) -> A210600 | AP20: Invoice dikasih sore jam 15:30.Invoice tanggal 03/02/2025,MB terima di tanggal 10/2/25.
A21: 45689 | B21: Invoiced | C21: SO | D21: 25707990 | E21: 24106534 | F21: POPD/GMC/24120456 | G21: 45695 | H21: PT. GRAND MULTI CHEMICALS JAKARTA-HI | I21: IF4851 | J21: PEACH FLAVOUR OS | K21: 5 | L21: KG | M21: 5 | N21: 1344896 | O21: 6724480 | P21: 6724480 | Q21: 0 | R21: 0 | S21: IDR | T21: 397383.6 | U21: 397383.6 | V21: 6327096.4 | W21: 0.94090493 | X21: 6327096.4 | Z21: . | AA21: 2306510 | AB21: PT. GRAND MULTI CHEMICALS TANGERANG-HI | AC21: Handy Inarto | AD21: 104 | AE21: 0 | AF21: 208 | AH21: . | AJ21: . | AK21: T | AL21: Non-Affiliate | AM21: Distributor | AN21: =VLOOKUP(I21,Sheet1!A:D,4,FALSE) -> A210600 | AP21: Invoice di kasih Jam 15:00, invoice tanggal 6/2/25. MB terima di tanggal 11/2/25
A22: 45689 | B22: Invoiced | C22: SO | D22: 25708015 | E22: 25106545 | F22: POPD/GMC/25010010 | G22: 45705 | H22: PT. GRAND MULTI CHEMICALS JAKARTA-AA | I22: IF2001 | J22: CHEDDAR CHEESE FLAVOUR | K22: 100 | L22: KG | M22: 100 | N22: 384604.43 | O22: 38460443 | P22: 38460443 | Q22: 0 | R22: 0 | S22: IDR | T22: 31119506 | U22: 31119506 | V22: 7340937 | W22: 0.1908698 | X22: 7340937 | Z22: . | AA22: 2306511 | AB22: PT. GRAND MULTI CHEMICALS TANGERANG-AA | AC22: AGNESYA ADIFILIA | AD22: 94 | AE22: 0 | AF22: 208 | AH22: . | AJ22: . | AK22: T | AL22: Non-Affiliate | AM22: Distributor | AN22: =VLOOKUP(I22,Sheet1!A:D,4,FALSE) -> A210600 | AP22: Invoice dikasih pas Mau Makan Siang, Invoice tgl 17,12,19,.MB terima Di tanggal 25/2/25. jam 12:25
A23: 45689 | B23: Invoiced | C23: SO | D23: 25708022 | E23: 25106616 | F23: POPD/GMC/25020072 | G23: 45712 | H23: PT. GRAND MULTI CHEMICALS JAKARTA-HI | I23: 9645360025 | J23: SWEET FLAVOR MSW 001 | K23: 50 | L23: KG | M23: 50 | N23: 901217.31 | O23: 45060866 | P23: 45060866 | Q23: 0 | R23: 0 | S23: IDR | T23: 31084931 | U23: 31084931 | V23: 13975934 | W23: 0.31015681 | X23: 13975934 | Z23: . | AA23: 2306510 | AB23: PT. GRAND MULTI CHEMICALS TANGERANG-HI | AC23: Handy Inarto | AD23: 104 | AE23: 0 | AF23: 102 | AH23: . | AJ23: . | AK23: T | AL23: Non-Affiliate | AM23: Distributor | AN23: =VLOOKUP(I23,Sheet1!A:D,4,FALSE) -> A210600 | AP23: Invoice dikasih sore tanggal 26/2/25. Invoice tanggal 19,24/2/25. MB terima di tanggal 26/2/25 jam 15:45
A24: 45689 | B24: Invoiced | C24: SO | D24: 25708023 | E24: 25106578 | F24: POPD/GMC/25010036 | G24: 45712 | H24: PT. GRAND MULTI CHEMICALS JAKARTA | I24: 9642640025 | J24: LZ 0414 | K24: 25 | L24: KG | M24: 25 | N24: 518045.16 | O24: 12951129 | P24: 12951129 | Q24: 0 | R24: 0 | S24: IDR | T24: 11581712 | U24: 11581712 | V24: 1369417 | W24: 0.10573727 | X24: 1369417 | Y24: DEL | Z24: Delivered | AA24: 15161 | AB24: PT. GRAND MULTI CHEMICALS TANGERANG | AC24: AGNESYA ADIFILIA | AD24: 94 | AE24: 0 | AF24: 101 | AH24: . | AJ24: . | AK24: T | AL24: Non-Affiliate | AM24: Distributor | AN24: =VLOOKUP(I24,Sheet1!A:D,4,FALSE) -> A210600 | AP24: Invoice dikasih sore tanggal 26/2/25. Invoice tanggal 19,24/2/25. MB terima di tanggal 26/2/25 jam 15:45
A25: 45689 | B25: Invoiced | C25: SO | D25: 25708027 | E25: 25106590 | F25: POPD/GMC/25010045 | G25: 45712 | H25: PT. GRAND MULTI CHEMICALS JAKARTA-AA | I25: 9637050025 | J25: SWEETEASE 3G FLAV N11839 25KG | K25: 50 | L25: KG | M25: 50 | N25: 505920 | O25: 25296000 | P25: 25296000 | Q25: 0 | R25: 0 | S25: IDR | T25: 16028611 | U25: 16028611 | V25: 9267389.1 | W25: 0.36635789 | X25: 9267389.1 | Z25: . | AA25: 2306511 | AB25: PT. GRAND MULTI CHEMICALS TANGERANG-AA | AC25: AGNESYA ADIFILIA | AD25: 94 | AE25: 0 | AF25: 101 | AH25: . | AJ25: . | AK25: T | AL25: Non-Affiliate | AM25: Distributor | AN25: =VLOOKUP(I25,Sheet1!A:D,4,FALSE) -> A210600 | AP25: Invoice dikasih sore tanggal 26/2/25. Invoice tanggal 19,24/2/25. MB terima di tanggal 26/2/25 jam 15:45
A26: 45717 | B26: Invoiced | C26: SO | D26: 25708037 | E26: 24106294 | F26: POPD/GMC/24070273 | G26: 45719 | H26: PT. GRAND MULTI CHEMICALS JAKARTA | I26: IDF2017 | J26: DB N2945 (FML10) 10KG | K26: 1000 | L26: KG | M26: 1000 | N26: 310898.82 | O26: 310898820 | P26: 310898820 | Q26: 0 | R26: 0 | S26: IDR | T26: 1.595273e+08 | U26: 1.595273e+08 | V26: 1.5137152e+08 | W26: 0.48688355 | X26: 1.5137152e+08 | Y26: DEL | Z26: Delivered | AA26: 15161 | AB26: PT. GRAND MULTI CHEMICALS TANGERANG | AC26: AGNESYA ADIFILIA | AD26: 94 | AE26: 0 | AF26: 202 | AH26: . | AJ26: . | AK26: M | AL26: Non-Affiliate | AM26: Distributor | AN26: =VLOOKUP(I26,Sheet1!A:D,4,FALSE) -> A210600 | AP26: Invoice dikasih Pagi jam 09:38 tanggal 7/3/25. Invoice tgl 03/3/25.MB terima ditanggal 07/3/25,abis Clossing Finance
A27: 45717 | B27: Invoiced | C27: SO | D27: 25708039 | E27: 25106579 | F27: POPD/GMC/25010037 | G27: 45719 | H27: PT. GRAND MULTI CHEMICALS JAKARTA | I27: 951090B003 | J27: CINNABON CARAMEL TOPPING @ | K27: 247.5 | L27: KG | M27: 247.5 | N27: 318924.9 | O27: 78933913 | P27: 78933913 | Q27: 0 | R27: 0 | S27: IDR | T27: 45294230 | U27: 45294230 | V27: 33639683 | W27: 0.42617528 | X27: 33639683 | Y27: DEL | Z27: Delivered | AA27: 15161 | AB27: PT. GRAND MULTI CHEMICALS TANGERANG | AC27: AGNESYA ADIFILIA | AD27: 94 | AE27: 0 | AF27: 308 | AG27: MKBR | AH27: MAN KET BROWN BASED | AJ27: . | AK27: T | AL27: Non-Affiliate | AM27: Distributor | AN27: =VLOOKUP(I27,Sheet1!A:D,4,FALSE) -> A210600 | AP27: Invoice dikasih Pagi jam 09:38 tanggal 7/3/25. Invoice tgl 03/3/25.MB terima ditanggal 07/3/25,abis Clossing Finance
A28: 45717 | B28: Invoiced | C28: SO | D28: 25708083 | E28: 25106571 | F28: POPD/GMC/25010029 | G28: 45734 | H28: PT. GRAND MULTI CHEMICALS JAKARTA | I28: IDF2005 | J28: DB XF1951 10KG | K28: 860 | L28: KG | M28: 860 | N28: 264315.3 | O28: 227311158 | P28: 227311158 | Q28: 0 | R28: 0 | S28: IDR | T28: 1.1809503e+08 | U28: 1.1809503e+08 | V28: 1.0921613e+08 | W28: 0.48046974 | X28: 1.0921613e+08 | Y28: DEL | Z28: Delivered | AA28: 15161 | AB28: PT. GRAND MULTI CHEMICALS TANGERANG | AC28: AGNESYA ADIFILIA | AD28: 94 | AE28: 0 | AF28: 202 | AH28: . | AJ28: . | AK28: M | AL28: Non-Affiliate | AM28: Distributor | AN28: =VLOOKUP(I28,Sheet1!A:D,4,FALSE) -> A210600 | AP28: Invoice di kasih sore jam pulang kerja.Invoice tgl 15/3/25. MB terima ditanggal 21/3/25. pagi
A29: 45717 | B29: Invoiced | C29: SO | D29: 25708084 | E29: 25106635 | F29: POPD/GMC/25030088 | G29: 45734 | H29: PT. GRAND MULTI CHEMICALS JAKARTA-AA | I29: 9637050025 | J29: SWEETEASE 3G FLAV N11839 25KG | K29: 50 | L29: KG | M29: 50 | N29: 512244 | O29: 25612200 | P29: 25612200 | Q29: 0 | R29: 0 | S29: IDR | T29: 17666414 | U29: 17666414 | V29: 7945786.4 | W29: 0.31023443 | X29: 7945786.4 | Z29: . | AA29: 2306511 | AB29: PT. GRAND MULTI CHEMICALS TANGERANG-AA | AC29: AGNESYA ADIFILIA | AD29: 94 | AE29: 0 | AF29: 101 | AH29: . | AJ29: . | AK29: T | AL29: Non-Affiliate | AM29: Distributor | AN29: =VLOOKUP(I29,Sheet1!A:D,4,FALSE) -> A210600 | AP29: Invoice di kasih sore jam pulang kerja.Invoice tgl 15/3/25. MB terima ditanggal 21/3/25. pagi
A30: 45717 | B30: Invoiced | C30: SO | D30: 25708086 | E30: 25106572 | F30: POPD/GMC/25010030 | G30: 45736 | H30: PT. GRAND MULTI CHEMICALS JAKARTA | I30: IDF2016 | J30: DB XF1745 10KG | K30: 850 | L30: KG | M30: 850 | N30: 322054.08 | O30: 273745968 | P30: 273745968 | Q30: 0 | R30: 0 | S30: IDR | T30: 1.2734945e+08 | U30: 1.2734945e+08 | V30: 1.4639652e+08 | W30: 0.53478969 | X30: 1.4639652e+08 | Y30: DEL | Z30: Delivered | AA30: 15161 | AB30: PT. GRAND MULTI CHEMICALS TANGERANG | AC30: AGNESYA ADIFILIA | AD30: 94 | AE30: 0 | AF30: 202 | AH30: . | AJ30: . | AK30: M | AL30: Non-Affiliate | AM30: Distributor | AN30: =VLOOKUP(I30,Sheet1!A:D,4,FALSE) -> A210600 | AP30: Invoice dikasih sore jam balik kerja 21/3/25 jam 17:30. Invaoice tgl 20/3/25. MB terima di tanggal 24/3/25 pagi
A31: 45717 | B31: Invoiced | C31: SO | D31: 25708087 | E31: 25106636 | F31: POPD/GMC/25030089 | G31: 45736 | H31: PT. GRAND MULTI CHEMICALS JAKARTA-HI | I31: 9645360025 | J31: SWEET FLAVOR MSW 001 | K31: 50 | L31: KG | M31: 50 | N31: 901217.31 | O31: 45060866 | P31: 45060866 | Q31: 0 | R31: 0 | S31: IDR | T31: 31072585 | U31: 31072585 | V31: 13988280 | W31: 0.3104308 | X31: 13988280 | Z31: . | AA31: 2306510 | AB31: PT. GRAND MULTI CHEMICALS TANGERANG-HI | AC31: Handy Inarto | AD31: 104 | AE31: 0 | AF31: 102 | AH31: . | AJ31: . | AK31: T | AL31: Non-Affiliate | AM31: Distributor | AN31: =VLOOKUP(I31,Sheet1!A:D,4,FALSE) -> A210600 | AP31: Invoice dikasih sore jam balik kerja 21/3/25 jam 17:30. Invaoice tgl 20/3/25. MB terima di tanggal 24/3/25 pagi
A32: 45717 | B32: Invoiced | C32: SO | D32: 25708088 | E32: 25106649 | F32: POPD/GMC/25030107 | G32: 45736 | H32: PT. GRAND MULTI CHEMICALS JAKARTA-HI | I32: 9643730025 | J32: SMOOTH FLAVOR MST 002 | K32: 5 | L32: KG | M32: 5 | N32: 860483.4 | O32: 4302417 | P32: 4302417 | Q32: 0 | R32: 0 | S32: IDR | T32: 3131134.3 | U32: 3131134.3 | V32: 1171282.7 | W32: 0.2722383 | X32: 1171282.7 | Z32: . | AA32: 2306510 | AB32: PT. GRAND MULTI CHEMICALS TANGERANG-HI | AC32: Handy Inarto | AD32: 104 | AE32: 0 | AF32: 101 | AH32: . | AJ32: . | AK32: T | AL32: Non-Affiliate | AM32: Distributor | AN32: =VLOOKUP(I32,Sheet1!A:D,4,FALSE) -> A210600 | AP32: Invoice dikasih sore jam balik kerja 21/3/25 jam 17:30. Invaoice tgl 20/3/25. MB terima di tanggal 24/3/25 pagi
A33: 45717 | B33: Invoiced | C33: SO | D33: 25708089 | E33: 25106650 | F33: POPD/GMC/25030106 | G33: 45736 | H33: PT. GRAND MULTI CHEMICALS JAKARTA-HI | I33: 9645360025 | J33: SWEET FLAVOR MSW 001 | K33: 5 | L33: KG | M33: 5 | N33: 901217.31 | O33: 4506086.5 | P33: 4506086.5 | Q33: 0 | R33: 0 | S33: IDR | T33: 3107258.5 | U33: 3107258.5 | V33: 1398828.1 | W33: 0.3104308 | X33: 1398828.1 | Z33: . | AA33: 2306510 | AB33: PT. GRAND MULTI CHEMICALS TANGERANG-HI | AC33: Handy Inarto | AD33: 104 | AE33: 0 | AF33: 102 | AH33: . | AJ33: . | AK33: T | AL33: Non-Affiliate | AM33: Distributor | AN33: =VLOOKUP(I33,Sheet1!A:D,4,FALSE) -> A210600 | AP33: Invoice dikasih sore jam balik kerja 21/3/25 jam 17:30. Invaoice tgl 20/3/25. MB terima di tanggal 24/3/25 pagi
A34: 45717 | B34: Invoiced | C34: SO | D34: 25708090 | E34: 24106539 | F34: POPD/GMC/24120469 | G34: 45740 | H34: PT. GRAND MULTI CHEMICALS JAKARTA | I34: 1109656820 | J34: CHEESEMATE 3036 | K34: 1600 | L34: KG | M34: 1600 | N34: 193951.97 | O34: 310323152 | P34: 310323152 | Q34: 0 | R34: 0 | S34: IDR | T34: 2.0708358e+08 | U34: 2.0708358e+08 | V34: 1.0323957e+08 | W34: 0.33268408 | X34: 1.0323957e+08 | Y34: DEL | Z34: Delivered | AA34: 15161 | AB34: PT. GRAND MULTI CHEMICALS TANGERANG | AC34: AGNESYA ADIFILIA | AD34: 94 | AE34: 0 | AF34: 973 | AG34: TSYB | AH34: TRA SAV YEAST BLEND CONC. | AJ34: . | AK34: T | AL34: Non-Affiliate | AM34: Distributor | AN34: =VLOOKUP(I34,Sheet1!A:D,4,FALSE) -> A210600 | AP34: Invoice dikasih Sore jam 16:00, Invoice tgl 25,21/03/2025. MB terima di tanggal 25/3/25. pagi
A35: 45717 | B35: Invoiced | C35: SO | D35: 25708091 | E35: 24106541 | F35: POPD/GMC/24120470 | G35: 45740 | H35: PT. GRAND MULTI CHEMICALS JAKARTA | I35: 1103880820 | J35: FSS-060301-SN | K35: 7000 | L35: KG | M35: 7000 | N35: 173227.91 | O35: 1212595370 | P35: 1212595370 | Q35: 0 | R35: 0 | S35: IDR | T35: 9.6803727e+08 | U35: 9.6803727e+08 | V35: 2.445581e+08 | W35: 0.20168154 | X35: 2.445581e+08 | Y35: DEL | Z35: Delivered | AA35: 15161 | AB35: PT. GRAND MULTI CHEMICALS TANGERANG | AC35: AGNESYA ADIFILIA | AD35: 94 | AE35: 0 | AF35: 201 | AG35: TSYE | AH35: TRA SAV YEAST EXTRACT | AJ35: . | AK35: T | AL35: Non-Affiliate | AM35: Distributor | AN35: =VLOOKUP(I35,Sheet1!A:D,4,FALSE) -> A210600 | AP35: Invoice dikasih Sore jam 16:00, Invoice tgl 25,21/03/2025. MB terima di tanggal 25/3/25. pagi
A36: 45748 | B36: Invoiced | C36: SO | D36: 25708125 | E36: 24106488 | F36: POPD/GMC/24120419 | G36: 45762 | H36: PT. GRAND MULTI CHEMICALS JAKARTA | I36: C15P.029-0020 | J36: BEETROOT P | K36: 680 | L36: KG | M36: 680 | N36: 120073.04 | O36: 81649667 | P36: 81649667 | Q36: 0 | R36: 0 | S36: IDR | T36: 64729923 | U36: 64729923 | V36: 16919744 | W36: 0.20722367 | X36: 16919744 | Y36: DEL | Z36: Delivered | AA36: 15161 | AB36: PT. GRAND MULTI CHEMICALS TANGERANG | AC36: AGNESYA ADIFILIA | AD36: 94 | AE36: 0 | AF36: 960 | AH36: . | AJ36: . | AK36: T | AL36: Non-Affiliate | AM36: Distributor | AN36: =VLOOKUP(I36,Sheet1!A:D,4,FALSE) -> A320400 | AP36: Invoice di kasih jam 11:30 tanggal 17/4/25.Invoice tanggal 14,1516.MB terima ditanggal 17/4/25.
